Workbook

Sheet 요약
A1: 방향 적응형 3-UWB 호흡 분석 | 개발군 검증 장부
A2: 독립검증군 17명은 잠금 상태이며 이 장부의 성능 수치는 이미 분석한 개발군 10명에만 해당합니다.
A4: 연구 설계 | B4: 값 | D4: 개발군 결과 | E4: 값
A5: 개발군 | B5: =COUNTIF('프로토콜_잠금'!$C$5:$C$34,"development") -> 10 | D5: 전체 RR MAE | E5: =SUM('개발_구간결과'!$AE$5:$AE$84)/SUM('개발_구간결과'!$AB$5:$AB$84) -> 0.50074269
A6: 잠금 독립검증군 | B6: =COUNTIF('프로토콜_잠금'!$C$5:$C$34,"independent_validation") -> 17 | D6: 채택 RR MAE | E6: =SUM('개발_구간결과'!$AD$5:$AD$84)/SUM('개발_구간결과'!$AC$5:$AC$84) -> 0.32436396
A7: 부분검토 | B7: =COUNTIF('프로토콜_잠금'!$C$5:$C$34,"partial_review") -> 2 | D7: 채택 coverage | E7: =SUM('개발_구간결과'!$AC$5:$AC$84)/SUM('개발_구간결과'!$AB$5:$AB$84) -> 0.98571429
A8: 제외 | B8: =COUNTIF('프로토콜_잠금'!$C$5:$C$34,"excluded") -> 1 | D8: ±2회/분 이내 | E8: =SUM('개발_구간결과'!$AF$5:$AF$84)/SUM('개발_구간결과'!$AB$5:$AB$84) -> 0.92857143
A9: 1·2번 공통 사용 | B9: =COUNTIF('프로토콜_잠금'!$E$5:$E$34,"usable_both") -> 27 | D9: 파형 |상관| 중앙값 | E9: 0.82753943
D10: 스쿼트 움직임 검출 | E10: 9/10
A12: 판정: 개발군 기준선은 개선됐지만 독립 성능은 아직 모릅니다. post-hold 실패와 S18 스쿼트 미관측을 해결하기 전 최종 ANN/SNN을 학습하지 않습니다.

Sheet 프로토콜_잠금
A1: 참가자별 실험 1·2 프로토콜 잠금
A2: M01-M04 선택과 개발/독립검증 분리를 모델 결과와 무관하게 기록합니다.
A4: number | B4: subject | C4: cohort | D4: blind_status | E4: usability | F4: m01_s | G4: m02_s | H4: s01_duration_s | I4: m03_s | J4: m04_s | K4: s02_duration_s | L4: s01_duration_qc | M4: s02_duration_qc | N4: decision_basis
A5: 1 | B5: S01_CMS | C5: partial_review | D5: not_applicable | E5: partial_review | F5: 58.512 | G5: 245.772 | H5: 187.26 | I5: 302.516 | J5: 729.192 | K5: 426.676 | L5: pass | M5: review | N5: M01-M02는 개연성 있음; M03-M04 426.7초로 S02 내부 라벨 불확실
A6: 2 | B6: S02_RJS | C6: independent_validation | D6: locked_not_evaluated | E6: usable_both | F6: 25 | G6: 217 | H6: 192 | I6: 245 | J6: 611 | K6: 366 | L6: pass | M6: pass | N6: 기존 전수검사 M01-M04 유지
A7: 3 | B7: S03_PSJ | C7: independent_validation | D7: locked_not_evaluated | E7: usable_both | F7: 23 | G7: 210 | H7: 187 | I7: 276 | J7: 646 | K7: 370 | L7: pass | M7: pass | N7: 기존 전수검사 M01-M04 유지
A8: 4 | B8: S04_KTW | C8: independent_validation | D8: locked_not_evaluated | E8: usable_both | F8: 22.63 | G8: 223.48 | H8: 200.85 | I8: 274.189 | J8: 647.224 | K8: 373.035 | L8: pass | M8: pass | N8: 후반 마커 문제와 무관하게 M01-M04 시간 범위 정상
A9: 5 | B9: S05_LHS | C9: independent_validation | D9: locked_not_evaluated | E9: usable_both | F9: 15 | G9: 210 | H9: 195 | I9: 241 | J9: 612 | K9: 371 | L9: pass | M9: pass | N9: 기존 전수검사 M01-M04 유지
A10: 6 | B10: S06_LDW | C10: independent_validation | D10: locked_not_evaluated | E10: usable_both | F10: 22 | G10: 214 | H10: 192 | I10: 264 | J10: 638 | K10: 374 | L10: pass | M10: pass | N10: 기존 전수검사 M01-M04 유지
A11: 7 | B11: S07_KDM | C11: development | D11: already_seen | E11: usable_both | F11: 16.572 | G11: 214.345 | H11: 197.773 | I11: 275.598 | J11: 646.78 | K11: 371.182 | L11: pass | M11: pass | N11: 기존 전수검사 M01-M04 유지
A12: 8 | B12: S08_MDO | C12: development | D12: already_seen | E12: usable_both | F12: 23.796 | G12: 220.164 | H12: 196.368 | I12: 260.444 | J12: 645.896 | K12: 385.452 | L12: pass | M12: pass | N12: 기존 전수검사 M01-M04 유지
A13: 9 | B13: S09_HDH | C13: development | D13: already_seen | E13: usable_both | F13: 16.915 | G13: 209.824 | H13: 192.909 | I13: 272.428 | J13: 647.296 | K13: 374.868 | L13: pass | M13: pass | N13: 기존 전수검사 M01-M04 유지
A14: 10 | B14: S10_JKH | C14: independent_validation | D14: locked_not_evaluated | E14: usable_both | F14: 26.144 | G14: 212.468 | H14: 186.324 | I14: 244.7 | J14: 625.824 | K14: 381.124 | L14: pass | M14: pass | N14: 기존 전수검사 M01-M04 유지
A15: 11 | B15: S11_SJE | C15: independent_validation | D15: locked_not_evaluated | E15: usable_both | F15: 15.264 | G15: 207.48133 | H15: 192.217 | I15: 260.616 | J15: 635.616 | K15: 375 | L15: pass | M15: pass | N15: 후반 마커 문제와 무관하게 M01-M04 시간 범위 정상
A16: 12 | B16: S12_KDH | C16: independent_validation | D16: locked_not_evaluated | E16: usable_both | F16: 24.524 | G16: 222.644 | H16: 198.12 | I16: 270.448 | J16: 646.804 | K16: 376.356 | L16: pass | M16: pass | N16: 자동 추천 M04=764.472 대신 원후보 646.804 채택
... A25: 21 | B25: S21_PSJ | C25: development | D25: already_seen | E25: usable_both | F25: 19.952 | G25: 214.06 | H25: 194.108 | I25: 235.404 | J25: 612.212 | K25: 376.808 | L25: pass | M25: pass | N25: 기존 전수검사 M01-M04 유지
A26: 22 | B26: S22_KJH | C26: partial_review | D26: not_applicable | E26: partial_review | G26: 222.04 | I26: 304.812 | J26: 681.412 | K26: 376.6 | L26: missing | M26: pass | N26: M01 누락; S02는 M03=304.812 후보 기준 376.6초
A27: 23 | B27: S23_KDM | C27: development | D27: already_seen | E27: usable_both | F27: 17.032 | G27: 212.8 | H27: 195.768 | I27: 229.692 | J27: 603.524 | K27: 373.832 | L27: pass | M27: pass | N27: 기존 전수검사 M01-M04 유지
A28: 24 | B28: S24_KHJ | C28: excluded | D28: not_applicable | E28: excluded | L28: missing | M28: missing | N28: UWB 원본 누락
A29: 25 | B29: S25_GEC | C29: independent_validation | D29: locked_not_evaluated | E29: usable_both | F29: 19 | G29: 216.6 | H29: 197.6 | I29: 237 | J29: 611.8 | K29: 374.8 | L29: pass | M29: pass | N29: 기존 전수검사 M01-M04 유지
A30: 26 | B30: S26_LDW | C30: development | D30: already_seen | E30: usable_both | F30: 12.588 | G30: 206.844 | H30: 194.256 | I30: 257.132 | J30: 633.06 | K30: 375.928 | L30: pass | M30: pass | N30: 기존 전수검사 M01-M04 유지
A31: 27 | B31: S27_HDH | C31: independent_validation | D31: locked_not_evaluated | E31: usable_both | F31: 6.2 | G31: 198.3 | H31: 192.1 | I31: 221.1 | J31: 596.9 | K31: 375.8 | L31: pass | M31: pass | N31: 기존 전수검사 M01-M04 유지
A32: 28 | B32: S28_KDH | C32: development | D32: already_seen | E32: usable_both | F32: 14.424 | G32: 207.58 | H32: 193.156 | I32: 238.924 | J32: 616.316 | K32: 377.392 | L32: pass | M32: pass | N32: 기존 전수검사 M01-M04 유지
A33: 29 | B33: S29_LHS | C33: independent_validation | D33: locked_not_evaluated | E33: usable_both | F33: 17.784 | G33: 209.824 | H33: 192.04 | I33: 232.384 | J33: 606.668 | K33: 374.284 | L33: pass | M33: pass | N33: 기존 전수검사 M01-M04 유지
A34: 30 | B34: S30_SJE | C34: independent_validation | D34: locked_not_evaluated | E34: usable_both | F34: 6.45 | G34: 192.15 | H34: 185.7 | I34: 237.275 | J34: 620.125 | K34: 382.85 | L34: pass | M34: pass | N34: 기존 전수검사 M01-M04 유지

Sheet 개발_구간결과
A1: 개발군 구간별 호흡수 결과
A2: SQUAT은 호흡수 평가에서 제외하고 움직임 거절 성능만 평가합니다.
A4: subject | B4: experiment | C4: state | D4: nominal_facing_radar | E4: start_s | F4: end_s | G4: duration_s | H4: rsp_rr_bpm | I4: radar1_rr_bpm | J4: radar2_rr_bpm | K4: radar3_rr_bpm | L4: radar1_primary_rr_bpm | M4: radar2_primary_rr_bpm | N4: radar3_primary_rr_bpm | O4: quality_best_radar | P4: quality_best_rr_bpm | Q4: consensus_rr_bpm | R4: radar_rr_mad_bpm | S4: edge_quality | T4: motion_quality | U4: max_motion_index | V4: confidence | W4: reject | X4: rr_abs_error | Y4: oracle_abs_error | Z4: waveform_abs_corr | AA4: median_motion_index | AB4: rr_evaluable | AC4: accepted_for_rr | AD4: accepted_error | AE4: all_error | AF4: within2
A5: S07_KDM | B5: S01 | C5: FACE_R1 | D5: 1 | E5: 30.459 | F5: 79.4 | G5: 48.941 | H5: 11.537368 | I5: 11.6559 | J5: 11.535088 | K5: 11.554222 | L5: 11.674359 | M5: 11.625014 | N5: 11.641951 | O5: 2 | P5: 11.535088 | Q5: 11.554222 | R5: 0.019133684 | S5: 1 | T5: 1 | U5: 0.030606469 | V5: 0.8741543844593515 | W5: 0 | X5: 0.016853623 | Y5: 0.0022800608 | Z5: 0.96874625 | AA5: 0.030066882 | AB5: =IF(C5="SQUAT",0,1) -> 1 | AC5: =IF(AND(AB5=1,W5=0),1,0) -> 1 | AD5: =IF(AC5=1,X5,"") -> 0.016853623 | AE5: =IF(AB5=1,X5,"") -> 0.016853623 | AF5: =IF(AB5=1,IF(X5<=2,1,0),"") -> 1
A6: S07_KDM | B6: S01 | C6: FACE_R2 | D6: 2 | E6: 89.4 | F6: 141.3 | G6: 51.9 | H6: 17.278966 | I6: 16.952714 | J6: 17.043484 | K6: 16.871437 | L6: 16.982492 | M6: 17.216889 | N6: 16.790587 | O6: 1 | P6: 16.952714 | Q6: 16.952714 | R6: 0.081276306 | S6: 1 | T6: 1 | U6: 0.029611614 | V6: 0.8486230480034661 | W6: 0 | X6: 0.32625217 | Y6: 0.23548219 | Z6: 0.85616043 | AA6: 0.028282656 | AB6: =IF(C6="SQUAT",0,1) -> 1 | AC6: =IF(AND(AB6=1,W6=0),1,0) -> 1 | AD6: =IF(AC6=1,X6,"") -> 0.32625217 | AE6: =IF(AB6=1,X6,"") -> 0.32625217 | AF6: =IF(AB6=1,IF(X6<=2,1,0),"") -> 1
A7: S07_KDM | B7: S01 | C7: FACE_R3 | D7: 3 | E7: 151.3 | F7: 209.345 | G7: 58.045 | H7: 11.208947 | I7: 12.306798 | J7: 11.120985 | K7: 11.051201 | L7: 11.553488 | M7: 11.267908 | N7: 10.881613 | O7: 2 | P7: 11.120985 | Q7: 11.120985 | R7: 0.069784662 | S7: 1 | T7: 1 | U7: 0.03119889 | V7: 0.8650405018405339 | W7: 0 | X7: 0.087961621 | Y7: 0.087961621 | Z7: 0.50387948 | AA7: 0.028120924 | AB7: =IF(C7="SQUAT",0,1) -> 1 | AC7: =IF(AND(AB7=1,W7=0),1,0) -> 1 | AD7: =IF(AC7=1,X7,"") -> 0.087961621 | AE7: =IF(AB7=1,X7,"") -> 0.087961621 | AF7: =IF(AB7=1,IF(X7<=2,1,0),"") -> 1
A8: S07_KDM | B8: S02 | C8: NORMAL | E8: 286.189 | F8: 336.189 | G8: 50 | H8: 15.587172 | I8: 16.201647 | J8: 14.08496 | K8: 16.272127 | L8: 16.272527 | M8: 14.146643 | N8: 16.280309 | O8: 3 | P8: 16.272127 | Q8: 16.201647 | R8: 0.070479517 | S8: 1 | T8: 1 | U8: 0.031215165 | V8: 0.8547197311618137 | W8: 0 | X8: 0.61447497 | Y8: 0.61447497 | Z8: 0.67641054 | AA8: 0.030431163 | AB8: =IF(C8="SQUAT",0,1) -> 1 | AC8: =IF(AND(AB8=1,W8=0),1,0) -> 1 | AD8: =IF(AC8=1,X8,"") -> 0.61447497 | AE8: =IF(AB8=1,X8,"") -> 0.61447497 | AF8: =IF(AB8=1,IF(X8<=2,1,0),"") -> 1
A9: S07_KDM | B9: S02 | C9: SLOW | E9: 346.189 | F9: 396.189 | G9: 50 | H9: 6.0213334 | I9: 5.9200195 | J9: 5.9314017 | K9: 5.9797552 | L9: 5.8646906 | M9: 5.8932067 | N9: 5.9477077 | O9: 3 | P9: 5.9797552 | Q9: 5.9314017 | R9: 0.011382192 | S9: 0.80628891 | T9: 1 | U9: 0.031648521 | V9: 0.8165209410220492 | W9: 0 | X9: 0.0899317 | Y9: 0.041578192 | Z9: 0.91291175 | AA9: 0.029006981 | AB9: =IF(C9="SQUAT",0,1) -> 1 | AC9: =IF(AND(AB9=1,W9=0),1,0) -> 1 | AD9: =IF(AC9=1,X9,"") -> 0.0899317 | AE9: =IF(AB9=1,X9,"") -> 0.0899317 | AF9: =IF(AB9=1,IF(X9<=2,1,0),"") -> 1
A10: S07_KDM | B10: S02 | C10: POST_HOLD | E10: 436.189 | F10: 486.189 | G10: 50 | H10: 11.412533 | I10: 11.500329 | J10: 11.726805 | K10: 11.282329 | L10: 11.313121 | M10: 11.889989 | N10: 11.277713 | O10: 3 | P10: 11.282329 | Q10: 11.500329 | R10: 0.21800043 | S10: 1 | T10: 1 | U10: 0.032211252 | V10: 0.8401850863553603 | W10: 0 | X10: 0.087795606 | Y10: 0.087795606 | Z10: 0.74294725 | AA10: 0.030958891 | AB10: =IF(C10="SQUAT",0,1) -> 1 | AC10: =IF(AND(AB10=1,W10=0),1,0) -> 1 | AD10: =IF(AC10=1,X10,"") -> 0.087795606 | AE10: =IF(AB10=1,X10,"") -> 0.087795606 | AF10: =IF(AB10=1,IF(X10<=2,1,0),"") -> 1
A11: S07_KDM | B11: S02 | C11: SQUAT | E11: 511.189 | F11: 561.189 | G11: 50 | H11: 22.079795 | I11: 14.366648 | J11: 10.976912 | K11: 11.71282 | L11: 14.462492 | M11: 10.954205 | N11: 11.712256 | O11: 1 | P11: 14.366648 | Q11: 11.71282 | R11: 0.73590788 | S11: 1 | T11: 0 | U11: 0.15569546 | V11: 0.6145999783212648 | W11: 1 | X11: 10.366975 | Y11: 7.7131472 | Z11: 0.29414127 | AA11: 0.079579759 | AB11: =IF(C11="SQUAT",0,1) -> 0 | AC11: =IF(AND(AB11=1,W11=0),1,0) -> 0 | AD11: =IF(AC11=1,X11,"") | AE11: =IF(AB11=1,X11,"") | AF11: =IF(AB11=1,IF(X11<=2,1,0),"")
A12: S07_KDM | B12: S02 | C12: POST_EXERCISE | E12: 586.189 | F12: 636.189 | G12: 50 | H12: 21.914253 | I12: 21.865989 | J12: 21.816558 | K12: 21.824771 | L12: 21.76117 | M12: 21.821438 | N12: 21.843625 | O12: 3 | P12: 21.824771 | Q12: 21.824771 | R12: 0.0082137058 | S12: 1 | T12: 1 | U12: 0.032234432 | V12: 0.8555773150696654 | W12: 0 | X12: 0.089481875 | Y12: 0.04826436 | Z12: 0.82749296 | AA12: 0.03125472 | AB12: =IF(C12="SQUAT",0,1) -> 1 | AC12: =IF(AND(AB12=1,W12=0),1,0) -> 1 | AD12: =IF(AC12=1,X12,"") -> 0.089481875 | AE12: =IF(AB12=1,X12,"") -> 0.089481875 | AF12: =IF(AB12=1,IF(X12<=2,1,0),"") -> 1
A13: S08_MDO | B13: S01 | C13: FACE_R1 | D13: 1 | E13: 36.98 | F13: 85.1 | G13: 48.12 | H13: 10.290275 | I13: 10.31621 | J13: 10.460557 | K13: 11.033514 | L13: 10.300655 | M13: 10.540893 | N13: 11.128124 | O13: 1 | P13: 10.31621 | Q13: 10.31621 | R13: 0.14434722 | S13: 0.73375845 | T13: 1 | U13: 0.028124239 | V13: 0.8156217252269141 | W13: 0 | X13: 0.025934873 | Y13: 0.025934873 | Z13: 0.94508263 | AA13: 0.025058695 | AB13: =IF(C13="SQUAT",0,1) -> 1 | AC13: =IF(AND(AB13=1,W13=0),1,0) -> 1 | AD13: =IF(AC13=1,X13,"") -> 0.025934873 | AE13: =IF(AB13=1,X13,"") -> 0.025934873 | AF13: =IF(AB13=1,IF(X13<=2,1,0),"") -> 1
A14: S08_MDO | B14: S01 | C14: FACE_R2 | D14: 2 | E14: 95.1 | F14: 146.8 | G14: 51.7 | H14: 10.433251 | I14: 10.482726 | J14: 10.381755 | K14: 10.251072 | L14: 10.61474 | M14: 10.38101 | N14: 10.243153 | O14: 2 | P14: 10.381755 | Q14: 10.381755 | R14: 0.1009706 | S14: 0.65762389 | T14: 1 | U14: 0.035140237 | V14: 0.7766231196711205 | W14: 0 | X14: 0.051495646 | Y14: 0.049474957 | Z14: 0.93017615 | AA14: 0.027306642 | AB14: =IF(C14="SQUAT",0,1) -> 1 | AC14: =IF(AND(AB14=1,W14=0),1,0) -> 1 | AD14: =IF(AC14=1,X14,"") -> 0.051495646 | AE14: =IF(AB14=1,X14,"") -> 0.051495646 | AF14: =IF(AB14=1,IF(X14<=2,1,0),"") -> 1
A15: S08_MDO | B15: S01 | C15: FACE_R3 | D15: 3 | E15: 156.8 | F15: 215.164 | G15: 58.364 | H15: 10.780079 | I15: 10.832059 | J15: 10.873485 | K15: 10.687887 | L15: 10.781902 | M15: 11.009801 | N15: 10.639887 | O15: 2 | P15: 10.873485 | Q15: 10.832059 | R15: 0.041425507 | S15: 0.84852465 | T15: 1 | U15: 0.030115209 | V15: 0.8290116409978617 | W15: 0 | X15: 0.051980254 | Y15: 0.051980254 | Z15: 0.85221339 | AA15: 0.02968026 | AB15: =IF(C15="SQUAT",0,1) -> 1 | AC15: =IF(AND(AB15=1,W15=0),1,0) -> 1 | AD15: =IF(AC15=1,X15,"") -> 0.051980254 | AE15: =IF(AB15=1,X15,"") -> 0.051980254 | AF15: =IF(AB15=1,IF(X15<=2,1,0),"") -> 1
A16: S08_MDO | B16: S02 | C16: NORMAL | E16: 278.17 | F16: 328.17 | G16: 50 | H16: 18.438432 | I16: 18.42081 | J16: 18.457638 | K16: 18.599925 | L16: 18.45335 | M16: 18.456983 | N16: 18.692619 | O16: 2 | P16: 18.457638 | Q16: 18.457638 | R16: 0.036827842 | S16: 1 | T16: 1 | U16: 0.031353275 | V16: 0.8859697427682197 | W16: 0 | X16: 0.019205812 | Y16: 0.017622029 | Z16: 0.84256952 | AA16: 0.031204142 | AB16: =IF(C16="SQUAT",0,1) -> 1 | AC16: =IF(AND(AB16=1,W16=0),1,0) -> 1 | AD16: =IF(AC16=1,X16,"") -> 0.019205812 | AE16: =IF(AB16=1,X16,"") -> 0.019205812 | AF16: =IF(AB16=1,IF(X16<=2,1,0),"") -> 1
A17: S08_MDO | B17: S02 | C17: SLOW | E17: 338.17 | F17: 388.17 | G17: 50 | H17: 5.9659786 | I17: 5.9574 | J17: 6.0612758 | K17: 5.9657787 | L17: 5.9328798 | M17: 6.0853335 | N17: 5.899393 | O17: 3 | P17: 5.9657787 | Q17: 5.9657787 | R17: 0.0083787692 | S17: 0.82518086 | T17: 1 | U17: 0.02856217 | V17: 0.8284844103642932 | W17: 0 | X17: 0.00019985825 | Y17: 0.00019985825 | Z17: 0.91232321 | AA17: 0.027327519 | AB17: =IF(C17="SQUAT",0,1) -> 1 | AC17: =IF(AND(AB17=1,W17=0),1,0) -> 1 | AD17: =IF(AC17=1,X17,"") -> 0.00019985825 | AE17: =IF(AB17=1,X17,"") -> 0.00019985825 | AF17: =IF(AB17=1,IF(X17<=2,1,0),"") -> 1
A18: S08_MDO | B18: S02 | C18: POST_HOLD | E18: 423.17 | F18: 478.17 | G18: 55 | H18: 11.318685 | I18: 11.304348 | J18: 11.326606 | K18: 11.312426 | L18: 11.403421 | M18: 11.359358 | N18: 11.324506 | O18: 1 | P18: 11.304348 | Q18: 11.312426 | R18: 0.008077932 | S18: 1 | T18: 1 | U18: 0.032060716 | V18: 0.8609750375135842 | W18: 0 | X18: 0.0062590802 | Y18: 0.0062590802 | Z18: 0.7333368 | AA18: 0.028209574 | AB18: =IF(C18="SQUAT",0,1) -> 1 | AC18: =IF(AND(AB18=1,W18=0),1,0) -> 1 | AD18: =IF(AC18=1,X18,"") -> 0.0062590802 | AE18: =IF(AB18=1,X18,"") -> 0.0062590802 | AF18: =IF(AB18=1,IF(X18<=2,1,0),"") -> 1
A19: S08_MDO | B19: S02 | C19: SQUAT | E19: 503.17 | F19: 553.17 | G19: 50 | H19: 11.753088 | I19: 31.407981 | J19: 11.810531 | K19: 12.14996 | L19: 31.418403 | M19: 11.811306 | N19: 11.489405 | O19: 2 | P19: 11.810531 | Q19: 11.810531 | R19: 0.33942946 | S19: 1 | T19: 0 | U19: 0.1193426 | V19: 0.6778446463538326 | W19: 1 | X19: 0.057442896 | Y19: 0.057442896 | Z19: 0.41489844 | AA19: 0.093388535 | AB19: =IF(C19="SQUAT",0,1) -> 0 | AC19: =IF(AND(AB19=1,W19=0),1,0) -> 0 | AD19: =IF(AC19=1,X19,"") | AE19: =IF(AB19=1,X19,"") | AF19: =IF(AB19=1,IF(X19<=2,1,0),"")
A20: S08_MDO | B20: S02 | C20: POST_EXERCISE | E20: 578.17 | F20: 628.17 | G20: 50 | H20: 28.26924 | I20: 28.33347 | J20: 28.265086 | K20: 28.249226 | L20: 28.373307 | M20: 28.236975 | N20: 28.213533 | O20: 2 | P20: 28.265086 | Q20: 28.265086 | R20: 0.015859292 | S20: 1 | T20: 1 | U20: 0.033658497 | V20: 0.8986812715493532 | W20: 0 | X20: 0.0041546932 | Y20: 0.0041546932 | Z20: 0.75594567 | AA20: 0.029752512 | AB20: =IF(C20="SQUAT",0,1) -> 1 | AC20: =IF(AND(AB20=1,W20=0),1,0) -> 1 | AD20: =IF(AC20=1,X20,"") -> 0.0041546932 | AE20: =IF(AB20=1,X20,"") -> 0.0041546932 | AF20: =IF(AB20=1,IF(X20<=2,1,0),"") -> 1
A21: S09_HDH | B21: S01 | C21: FACE_R1 | D21: 1 | E21: 28.37 | F21: 80.9 | G21: 52.53 | H21: 14.614892 | I21: 14.676989 | J21: 14.617073 | K21: 14.738566 | L21: 14.618189 | M21: 14.622822 | N21: 14.722666 | O21: 1 | P21: 14.676989 | Q21: 14.676989 | R21: 0.059916147 | S21: 1 | T21: 1 | U21: 0.034236769 | V21: 0.8736485646036783 | W21: 0 | X21: 0.062097125 | Y21: 0.002180978 | Z21: 0.74994022 | AA21: 0.030639479 | AB21: =IF(C21="SQUAT",0,1) -> 1 | AC21: =IF(AND(AB21=1,W21=0),1,0) -> 1 | AD21: =IF(AC21=1,X21,"") -> 0.062097125 | AE21: =IF(AB21=1,X21,"") -> 0.062097125 | AF21: =IF(AB21=1,IF(X21<=2,1,0),"") -> 1
A22: S09_HDH | B22: S01 | C22: FACE_R2 | D22: 2 | E22: 90.9 | F22: 141.9 | G22: 51 | H22: 16.802957 | I22: 16.761512 | J22: 16.592185 | K22: 16.532136 | L22: 16.929712 | M22: 17.165256 | N22: 16.601414 | O22: 3 | P22: 16.532136 | Q22: 16.592185 | R22: 0.060049275 | S22: 1 | T22: 1 | U22: 0.028333324 | V22: 0.8699417531824182 | W22: 0 | X22: 0.21077178 | Y22: 0.04144528 | Z22: 0.74034318 | AA22: 0.027165917 | AB22: =IF(C22="SQUAT",0,1) -> 1 | AC22: =IF(AND(AB22=1,W22=0),1,0) -> 1 | AD22: =IF(AC22=1,X22,"") -> 0.21077178 | AE22: =IF(AB22=1,X22,"") -> 0.21077178 | AF22: =IF(AB22=1,IF(X22<=2,1,0),"") -> 1
A23: S09_HDH | B23: S01 | C23: FACE_R3 | D23: 3 | E23: 151.9 | F23: 204.824 | G23: 52.924 | H23: 18.045673 | I23: 18.232617 | J23: 18.10393 | K23: 17.971573 | L23: 18.179115 | M23: 18.024877 | N23: 17.895894 | O23: 3 | P23: 17.971573 | Q23: 18.10393 | R23: 0.12868634 | S23: 1 | T23: 1 | U23: 0.028696223 | V23: 0.8366674709634211 | W23: 0 | X23: 0.058257919 | Y23: 0.058257919 | Z23: 0.5392338 | AA23: 0.025937238 | AB23: =IF(C23="SQUAT",0,1) -> 1 | AC23: =IF(AND(AB23=1,W23=0),1,0) -> 1 | AD23: =IF(AC23=1,X23,"") -> 0.058257919 | AE23: =IF(AB23=1,X23,"") -> 0.058257919 | AF23: =IF(AB23=1,IF(X23<=2,1,0),"") -> 1
A24: S09_HDH | B24: S02 | C24: NORMAL | E24: 284.862 | F24: 334.862 | G24: 50 | H24: 16.255141 | I24: 16.008601 | J24: 16.067043 | K24: 16.168286 | L24: 16.095195 | M24: 16.128092 | N24: 16.190136 | O24: 1 | P24: 16.008601 | Q24: 16.067043 | R24: 0.058442006 | S24: 1 | T24: 1 | U24: 0.025881528 | V24: 0.8663547775883701 | W24: 0 | X24: 0.18809844 | Y24: 0.086855174 | Z24: 0.86689566 | AA24: 0.025359376 | AB24: =IF(C24="SQUAT",0,1) -> 1 | AC24: =IF(AND(AB24=1,W24=0),1,0) -> 1 | AD24: =IF(AC24=1,X24,"") -> 0.18809844 | AE24: =IF(AB24=1,X24,"") -> 0.18809844 | AF24: =IF(AB24=1,IF(X24<=2,1,0),"") -> 1
A25: S09_HDH | B25: S02 | C25: SLOW | E25: 344.862 | F25: 394.862 | G25: 50 | H25: 6.1271074 | I25: 6.0075426 | J25: 5.7810161 | K25: 6.0123817 | L25: 5.9873168 | M25: 5.823199 | N25: 6.0534371 | O25: 3 | P25: 6.0123817 | Q25: 6.0075426 | R25: 0.0048390855 | S25: 0.85110324 | T25: 1 | U25: 0.027751209 | V25: 0.8289216748242861 | W25: 0 | X25: 0.11956479 | Y25: 0.1147257 | Z25: 0.87195056 | AA25: 0.026802069 | AB25: =IF(C25="SQUAT",0,1) -> 1 | AC25: =IF(AND(AB25=1,W25=0),1,0) -> 1 | AD25: =IF(AC25=1,X25,"") -> 0.11956479 | AE25: =IF(AB25=1,X25,"") -> 0.11956479 | AF25: =IF(AB25=1,IF(X25<=2,1,0),"") -> 1
A26: S09_HDH | B26: S02 | C26: POST_HOLD | E26: 434.862 | F26: 484.862 | G26: 50 | H26: 11.707696 | I26: 11.665543 | J26: 11.701943 | K26: 11.662016 | L26: 11.669049 | M26: 11.813247 | N26: 11.739367 | O26: 1 | P26: 11.665543 | Q26: 11.665543 | R26: 0.0035276933 | S26: 1 | T26: 1 | U26: 0.028283974 | V26: 0.8569580202148969 | W26: 0 | X26: 0.04215231 | Y26: 0.0057527246 | Z26: 0.72743815 | AA26: 0.02756343 | AB26: =IF(C26="SQUAT",0,1) -> 1 | AC26: =IF(AND(AB26=1,W26=0),1,0) -> 1 | AD26: =IF(AC26=1,X26,"") -> 0.04215231 | AE26: =IF(AB26=1,X26,"") -> 0.04215231 | AF26: =IF(AB26=1,IF(X26<=2,1,0),"") -> 1
A27: S09_HDH | B27: S02 | C27: SQUAT | E27: 509.862 | F27: 559.862 | G27: 50 | H27: 16.489153 | I27: 16.648299 | J27: 16.914418 | K27: 16.784687 | L27: 16.602772 | M27: 16.875985 | N27: 16.736256 | O27: 3 | P27: 16.784687 | Q27: 16.784687 | R27: 0.12973075 | S27: 1 | T27: 0 | U27: 0.096250562 | V27: 0.7563754464485732 | W27: 1 | X27: 0.29553434 | Y27: 0.15914598 | Z27: 0.5270385 | AA27: 0.087836619 | AB27: =IF(C27="SQUAT",0,1) -> 0 | AC27: =IF(AND(AB27=1,W27=0),1,0) -> 0 | AD27: =IF(AC27=1,X27,"") | AE27: =IF(AB27=1,X27,"") | AF27: =IF(AB27=1,IF(X27<=2,1,0),"")
A28: S09_HDH | B28: S02 | C28: POST_EXERCISE | E28: 584.862 | F28: 634.862 | G28: 50 | H28: 13.804994 | I28: 15.999591 | J28: 11.483685 | K28: 10.717028 | L28: 16.000948 | M28: 11.598242 | N28: 10.502264 | O28: 2 | P28: 11.483685 | Q28: 11.483685 | R28: 0.766657 | S28: 1 | T28: 1 | U28: 0.034340076 | V28: 0.7365092092312489 | W28: 0 | X28: 2.3213089 | Y28: 2.1945969 | Z28: 0.22611498 | AA28: 0.032433696 | AB28: =IF(C28="SQUAT",0,1) -> 1 | AC28: =IF(AND(AB28=1,W28=0),1,0) -> 1 | AD28: =IF(AC28=1,X28,"") -> 2.3213089 | AE28: =IF(AB28=1,X28,"") -> 2.3213089 | AF28: =IF(AB28=1,IF(X28<=2,1,0),"") -> 0
A29: S17_RJS | B29: S01 | C29: FACE_R1 | D29: 1 | E29: 27.841 | F29: 81 | G29: 53.159 | H29: 14.667131 | I29: 14.779436 | J29: 14.821746 | K29: 15.008803 | L29: 14.860628 | M29: 14.839186 | N29: 14.739427 | O29: 2 | P29: 14.821746 | Q29: 14.821746 | R29: 0.042309144 | S29: 1 | T29: 1 | U29: 0.034420623 | V29: 0.8720471762001786 | W29: 0 | X29: 0.15461499 | Y29: 0.11230584 | Z29: 0.92465429 | AA29: 0.027342398 | AB29: =IF(C29="SQUAT",0,1) -> 1 | AC29: =IF(AND(AB29=1,W29=0),1,0) -> 1 | AD29: =IF(AC29=1,X29,"") -> 0.15461499 | AE29: =IF(AB29=1,X29,"") -> 0.15461499 | AF29: =IF(AB29=1,IF(X29<=2,1,0),"") -> 1
A30: S17_RJS | B30: S01 | C30: FACE_R2 | D30: 2 | E30: 91 | F30: 143.2 | G30: 52.2 | H30: 13.307254 | I30: 13.48723 | J30: 13.428375 | K30: 13.718298 | L30: 13.488895 | M30: 13.511127 | N30: 13.822297 | O30: 1 | P30: 13.48723 | Q30: 13.48723 | R30: 0.058854814 | S30: 1 | T30: 1 | U30: 0.030158551 | V30: 0.8714131183296735 | W30: 0 | X30: 0.17997597 | Y30: 0.12112116 | Z30: 0.86314786 | AA30: 0.029757094 | AB30: =IF(C30="SQUAT",0,1) -> 1 | AC30: =IF(AND(AB30=1,W30=0),1,0) -> 1 | AD30: =IF(AC30=1,X30,"") -> 0.17997597 | AE30: =IF(AB30=1,X30,"") -> 0.17997597 | AF30: =IF(AB30=1,IF(X30<=2,1,0),"") -> 1
A31: S17_RJS | B31: S01 | C31: FACE_R3 | D31: 3 | E31: 153.2 | F31: 204.809 | G31: 51.609 | H31: 15.625819 | I31: 15.386099 | J31: 15.5827 | K31: 15.59985 | L31: 15.435189 | M31: 15.606461 | N31: 15.634153 | O31: 3 | P31: 15.59985 | Q31: 15.5827 | R31: 0.017149589 | S31: 1 | T31: 1 | U31: 0.02926516 | V31: 0.8808080309239562 | W31: 0 | X31: 0.043118835 | Y31: 0.025969246 | Z31: 0.87203018 | AA31: 0.027525935 | AB31: =IF(C31="SQUAT",0,1) -> 1 | AC31: =IF(AND(AB31=1,W31=0),1,0) -> 1 | AD31: =IF(AC31=1,X31,"") -> 0.043118835 | AE31: =IF(AB31=1,X31,"") -> 0.043118835 | AF31: =IF(AB31=1,IF(X31<=2,1,0),"") -> 1
A32: S17_RJS | B32: S02 | C32: NORMAL | E32: 243.63 | F32: 293.63 | G32: 50 | H32: 16.900554 | I32: 16.930658 | J32: 17.38224 | K32: 16.492693 | L32: 16.809567 | M32: 17.552171 | N32: 16.46089 | O32: 1 | P32: 16.930658 | Q32: 16.930658 | R32: 0.43796485 | S32: 1 | T32: 1 | U32: 0.029149334 | V32: 0.7955903211043734 | W32: 0 | X32: 0.030104044 | Y32: 0.030104044 | Z32: 0.78203177 | AA32: 0.027289062 | AB32: =IF(C32="SQUAT",0,1) -> 1 | AC32: =IF(AND(AB32=1,W32=0),1,0) -> 1 | AD32: =IF(AC32=1,X32,"") -> 0.030104044 | AE32: =IF(AB32=1,X32,"") -> 0.030104044 | AF32: =IF(AB32=1,IF(X32<=2,1,0),"") -> 1
A33: S17_RJS | B33: S02 | C33: SLOW | E33: 303.63 | F33: 353.63 | G33: 50 | H33: 5.9883127 | I33: 5.9801519 | J33: 5.9794284 | K33: 5.998041 | L33: 6.1066281 | M33: 5.9552411 | N33: 5.982154 | O33: 1 | P33: 5.9801519 | Q33: 5.9801519 | R33: 0.00072347413 | S33: 0.84864478 | T33: 1 | U33: 0.029808219 | V33: 0.8304389347044 | W33: 0 | X33: 0.0081607888 | Y33: 0.0081607888 | Z33: 0.87266906 | AA33: 0.028198923 | AB33: =IF(C33="SQUAT",0,1) -> 1 | AC33: =IF(AND(AB33=1,W33=0),1,0) -> 1 | AD33: =IF(AC33=1,X33,"") -> 0.0081607888 | AE33: =IF(AB33=1,X33,"") -> 0.0081607888 | AF33: =IF(AB33=1,IF(X33<=2,1,0),"") -> 1
A34: S17_RJS | B34: S02 | C34: POST_HOLD | E34: 393.25 | F34: 443.63 | G34: 50.38 | H34: 15.953072 | I34: 12.322079 | J34: 12.2716 | K34: 12.146666 | L34: 12.390901 | M34: 12.278132 | N34: 11.995747 | O34: 3 | P34: 12.146666 | Q34: 12.2716 | R34: 0.050479236 | S34: 1 | T34: 1 | U34: 0.02916279 | V34: 0.8606799817446732 | W34: 0 | X34: 3.681472 | Y34: 3.6309928 | Z34: 0.58739128 | AA34: 0.026706275 | AB34: =IF(C34="SQUAT",0,1) -> 1 | AC34: =IF(AND(AB34=1,W34=0),1,0) -> 1 | AD34: =IF(AC34=1,X34,"") -> 3.681472 | AE34: =IF(AB34=1,X34,"") -> 3.681472 | AF34: =IF(AB34=1,IF(X34<=2,1,0),"") -> 0
A35: S17_RJS | B35: S02 | C35: SQUAT | E35: 468.63 | F35: 518.63 | G35: 50 | H35: 32.958984 | I35: 10.795096 | J35: 30.438557 | K35: 30.723867 | L35: 10.797465 | M35: 30.366312 | N35: 30.701257 | O35: 3 | P35: 30.723867 | Q35: 30.723867 | R35: 0.28530917 | S35: 1 | T35: 0 | U35: 0.18224038 | V35: 0.6965558945421905 | W35: 1 | X35: 2.2351178 | Y35: 2.2351178 | Z35: 0.51471569 | AA35: 0.11812471 | AB35: =IF(C35="SQUAT",0,1) -> 0 | AC35: =IF(AND(AB35=1,W35=0),1,0) -> 0 | AD35: =IF(AC35=1,X35,"") | AE35: =IF(AB35=1,X35,"") | AF35: =IF(AB35=1,IF(X35<=2,1,0),"")
A36: S17_RJS | B36: S02 | C36: POST_EXERCISE | E36: 543.63 | F36: 593.63 | G36: 50 | H36: 25.945371 | I36: 26.043384 | J36: 25.974929 | K36: 25.92222 | L36: 25.959189 | M36: 25.99764 | N36: 25.9975 | O36: 3 | P36: 25.92222 | Q36: 25.974929 | R36: 0.052709389 | S36: 1 | T36: 1 | U36: 0.031447523 | V36: 0.8627498947873974 | W36: 0 | X36: 0.029558169 | Y36: 0.02315122 | Z36: 0.52570069 | AA36: 0.029704367 | AB36: =IF(C36="SQUAT",0,1) -> 1 | AC36: =IF(AND(AB36=1,W36=0),1,0) -> 1 | AD36: =IF(AC36=1,X36,"") -> 0.029558169 | AE36: =IF(AB36=1,X36,"") -> 0.029558169 | AF36: =IF(AB36=1,IF(X36<=2,1,0),"") -> 1
A37: S18_LJH | B37: S01 | C37: FACE_R1 | D37: 1 | E37: 28.488 | F37: 78 | G37: 49.512 | H37: 16.37376 | I37: 16.345898 | J37: 16.38974 | K37: 16.091248 | L37: 16.34919 | M37: 16.311604 | N37: 15.885103 | O37: 1 | P37: 16.345898 | Q37: 16.345898 | R37: 0.043842091 | S37: 1 | T37: 1 | U37: 0.031334669 | V37: 0.8749900585550267 | W37: 0 | X37: 0.027861998 | Y37: 0.015980093 | Z37: 0.94303367 | AA37: 0.025430699 | AB37: =IF(C37="SQUAT",0,1) -> 1 | AC37: =IF(AND(AB37=1,W37=0),1,0) -> 1 | AD37: =IF(AC37=1,X37,"") -> 0.027861998 | AE37: =IF(AB37=1,X37,"") -> 0.027861998 | AF37: =IF(AB37=1,IF(X37<=2,1,0),"") -> 1
A38: S18_LJH | B38: S01 | C38: FACE_R2 | D38: 2 | E38: 88 | F38: 139.9 | G38: 51.9 | H38: 17.116629 | I38: 17.098857 | J38: 17.12367 | K38: 17.095791 | L38: 17.105681 | M38: 17.12492 | N38: 17.074164 | O38: 2 | P38: 17.12367 | Q38: 17.098857 | R38: 0.003066202 | S38: 1 | T38: 1 | U38: 0.031850625 | V38: 0.8699928192842975 | W38: 0 | X38: 0.01777188 | Y38: 0.0070416767 | Z38: 0.9253185 | AA38: 0.030447777 | AB38: =IF(C38="SQUAT",0,1) -> 1 | AC38: =IF(AND(AB38=1,W38=0),1,0) -> 1 | AD38: =IF(AC38=1,X38,"") -> 0.01777188 | AE38: =IF(AB38=1,X38,"") -> 0.01777188 | AF38: =IF(AB38=1,IF(X38<=2,1,0),"") -> 1
A39: S18_LJH | B39: S01 | C39: FACE_R3 | D39: 3 | E39: 149.9 | F39: 206.68 | G39: 56.78 | H39: 14.818155 | I39: 14.768888 | J39: 14.754534 | K39: 14.724435 | L39: 14.754849 | M39: 14.758106 | N39: 14.702654 | O39: 3 | P39: 14.724435 | Q39: 14.754534 | R39: 0.014354565 | S39: 1 | T39: 1 | U39: 0.030015601 | V39: 0.8770091258078391 | W39: 0 | X39: 0.063621211 | Y39: 0.049266647 | Z39: 0.92539263 | AA39: 0.025810634 | AB39: =IF(C39="SQUAT",0,1) -> 1 | AC39: =IF(AND(AB39=1,W39=0),1,0) -> 1 | AD39: =IF(AC39=1,X39,"") -> 0.063621211 | AE39: =IF(AB39=1,X39,"") -> 0.063621211 | AF39: =IF(AB39=1,IF(X39<=2,1,0),"") -> 1
A40: S18_LJH | B40: S02 | C40: NORMAL | E40: 242.434 | F40: 292.434 | G40: 50 | H40: 17.881074 | I40: 18.007339 | J40: 17.797982 | K40: 17.626723 | L40: 17.961397 | M40: 17.843364 | N40: 17.598953 | O40: 2 | P40: 17.797982 | Q40: 17.797982 | R40: 0.17125883 | S40: 1 | T40: 1 | U40: 0.032464581 | V40: 0.8282147605008036 | W40: 0 | X40: 0.083092699 | Y40: 0.083092699 | Z40: 0.7644542 | AA40: 0.030864732 | AB40: =IF(C40="SQUAT",0,1) -> 1 | AC40: =IF(AND(AB40=1,W40=0),1,0) -> 1 | AD40: =IF(AC40=1,X40,"") -> 0.083092699 | AE40: =IF(AB40=1,X40,"") -> 0.083092699 | AF40: =IF(AB40=1,IF(X40<=2,1,0),"") -> 1
A41: S18_LJH | B41: S02 | C41: SLOW | E41: 302.434 | F41: 352.434 | G41: 50 | H41: 6.0252876 | I41: 6.0237644 | J41: 6.0422234 | K41: 6.0739545 | L41: 6.1279246 | M41: 6.0069938 | N41: 6.1186317 | O41: 2 | P41: 6.0422234 | Q41: 6.0422234 | R41: 0.01845902 | S41: 0.91363415 | T41: 1 | U41: 0.032073048 | V41: 0.8534994357328064 | W41: 0 | X41: 0.016935752 | Y41: 0.0015232674 | Z41: 0.96517957 | AA41: 0.029945292 | AB41: =IF(C41="SQUAT",0,1) -> 1 | AC41: =IF(AND(AB41=1,W41=0),1,0) -> 1 | AD41: =IF(AC41=1,X41,"") -> 0.016935752 | AE41: =IF(AB41=1,X41,"") -> 0.016935752 | AF41: =IF(AB41=1,IF(X41<=2,1,0),"") -> 1
...

Sheet 레이더별_관측
A1: 레이더별·거리 경로 관측
A2: 각 레이더의 주 경로와 보조 경로 후보, 레이더 자체 품질 및 사후 BIOPAC 오차를 분리해 기록합니다.
A4: subject | B4: experiment | C4: state | D4: nominal_facing_radar | E4: radar | F4: start_s | G4: end_s | H4: duration_s | I4: rsp_rr_bpm | J4: primary_bin | K4: auxiliary_bin | L4: auxiliary_corr | M4: radar_rr_bpm | N4: primary_rr_bpm | O4: path_fused_rr_bpm | P4: primary_rr_abs_error | Q4: path_fused_rr_abs_error | R4: rr_abs_error | S4: quality | T4: phase_bad | U4: spectral_entropy | V4: peak_fraction | W4: edge_margin_hz | X4: motion_index
A5: S07_KDM | B5: S01 | C5: FACE_R1 | D5: 1 | E5: 1 | F5: 30.459 | G5: 79.4 | H5: 48.941 | I5: 11.537368 | J5: 67 | K5: 78 | L5: -0.76950414 | M5: 11.6559 | N5: 11.674359 | O5: 11.6559 | P5: 0.13699126 | Q5: 0.11853196 | R5: 0.11853196 | S5: 1.9855762428860007 | T5: 0.009197751660705161 | U5: 0.74535056 | V5: 0.11634903 | W5: 0.044572654 | X5: 0.030066882
A6: S07_KDM | B6: S01 | C6: FACE_R1 | D6: 1 | E6: 2 | F6: 30.459 | G6: 79.4 | H6: 48.941 | I6: 11.537368 | J6: 19 | K6: 75 | L6: 0.79431591 | M6: 11.535088 | N6: 11.625014 | O6: 11.535088 | P6: 0.087646113 | Q6: 0.0022800608 | R6: 0.0022800608 | S6: 3.0873724832315403 | T6: 0.0 | U6: 0.66979296 | V6: 0.12356178 | W6: 0.043750235 | X6: 0.030606469
A7: S07_KDM | B7: S01 | C7: FACE_R1 | D7: 1 | E7: 3 | F7: 30.459 | G7: 79.4 | H7: 48.941 | I7: 11.537368 | J7: 12 | K7: 78 | L7: 0.73767073 | M7: 11.554222 | N7: 11.641951 | O7: 11.554222 | P7: 0.10458271 | Q7: 0.016853623 | R7: 0.016853623 | S7: 1.7050823840925915 | T7: 0.0 | U7: 0.63147521 | V7: 0.13485608 | W7: 0.044032512 | X7: 0.023423434
A8: S07_KDM | B8: S01 | C8: FACE_R2 | D8: 2 | E8: 1 | F8: 89.4 | G8: 141.3 | H8: 51.9 | I8: 17.278966 | J8: 14 | K8: 23 | L8: 0.92584248 | M8: 16.952714 | N8: 16.982492 | O8: 16.952714 | P8: 0.2964736 | Q8: 0.32625217 | R8: 0.32625217 | S8: 2.236861632937049 | T8: 0.0 | U8: 0.74753199 | V8: 0.099265001 | W8: 0.13304154 | X8: 0.028282656
A9: S07_KDM | B9: S01 | C9: FACE_R2 | D9: 2 | E9: 2 | F9: 89.4 | G9: 141.3 | H9: 51.9 | I9: 17.278966 | J9: 29 | K9: 64 | L9: 0.78532837 | M9: 17.043484 | N9: 17.216889 | O9: 17.043484 | P9: 0.062076268 | Q9: 0.23548219 | R9: 0.23548219 | S9: 1.4496355953735396 | T9: 0.005301204819277108 | U9: 0.78140268 | V9: 0.09386023 | W9: 0.13694816 | X9: 0.029611614
A10: S07_KDM | B10: S01 | C10: FACE_R2 | D10: 2 | E10: 3 | F10: 89.4 | G10: 141.3 | H10: 51.9 | I10: 17.278966 | J10: 16 | K10: 28 | L10: -0.88359145 | M10: 16.871437 | N10: 16.790587 | O10: 16.871437 | P10: 0.48837826 | Q10: 0.40752848 | R10: 0.40752848 | S10: 2.0614077325322593 | T10: 0.0 | U10: 0.74347464 | V10: 0.094482275 | W10: 0.12984312 | X10: 0.026469473
A11: S07_KDM | B11: S01 | C11: FACE_R3 | D11: 3 | E11: 1 | F11: 151.3 | G11: 209.345 | H11: 58.045 | I11: 11.208947 | J11: 11 | K11: 73 | L11: -0.6526159 | M11: 12.306798 | N11: 11.553488 | O11: 12.306798 | P11: 0.34454059 | Q11: 1.0978511 | R11: 1.0978511 | S11: 0.9957296497926186 | T11: 0.0008616975441619991 | U11: 0.70698756 | V11: 0.092336149 | W11: 0.042558127 | X11: 0.026325601
A12: S07_KDM | B12: S01 | C12: FACE_R3 | D12: 3 | E12: 2 | F12: 151.3 | G12: 209.345 | H12: 58.045 | I12: 11.208947 | J12: 68 | K12: 32 | L12: 0.75546539 | M12: 11.120985 | N12: 11.267908 | O12: 11.120985 | P12: 0.058960904 | Q12: 0.087961621 | R12: 0.087961621 | S12: 2.2794500041479178 | T12: 0.005601034037052995 | U12: 0.6751428 | V12: 0.11336197 | W12: 0.037798465 | X12: 0.03119889
A13: S07_KDM | B13: S01 | C13: FACE_R3 | D13: 3 | E13: 3 | F13: 151.3 | G13: 209.345 | H13: 58.045 | I13: 11.208947 | J13: 32 | K13: 77 | L13: 0.79089223 | M13: 11.051201 | N13: 10.881613 | O13: 11.051201 | P13: 0.32733403 | Q13: 0.15774628 | R13: 0.15774628 | S13: 1.4928548972077023 | T13: 0.004308487720809996 | U13: 0.78385412 | V13: 0.093693813 | W13: 0.031360216 | X13: 0.028120924
A14: S07_KDM | B14: S02 | C14: NORMAL | E14: 1 | F14: 286.189 | G14: 336.189 | H14: 50 | I14: 15.587172 | J14: 73 | K14: 15 | L14: -0.77868778 | M14: 16.201647 | N14: 16.272527 | O14: 16.201647 | P14: 0.68535424 | Q14: 0.61447497 | R14: 0.61447497 | S14: 1.0320401453410792 | T14: 0.0 | U14: 0.7819456 | V14: 0.077847398 | W14: 0.12120878 | X14: 0.031215165
A15: S07_KDM | B15: S02 | C15: NORMAL | E15: 2 | F15: 286.189 | G15: 336.189 | H15: 50 | I15: 15.587172 | J15: 65 | K15: 79 | L15: -0.75698931 | M15: 14.08496 | N15: 14.146643 | O15: 14.08496 | P15: 1.4405294 | Q15: 1.5022125 | R15: 1.5022125 | S15: 1.0032357818974775 | T15: 0.0015 | U15: 0.84022794 | V15: 0.060635374 | W15: 0.08577738 | X15: 0.030431163
A16: S07_KDM | B16: S02 | C16: NORMAL | E16: 3 | F16: 286.189 | G16: 336.189 | H16: 50 | I16: 15.587172 | J16: 61 | K16: 14 | L16: 0.76722204 | M16: 16.272127 | N16: 16.280309 | O16: 16.272127 | P16: 0.69313709 | Q16: 0.68495449 | R16: 0.68495449 | S16: 1.4036933266027742 | T16: 0.0 | U16: 0.73505286 | V16: 0.098069681 | W16: 0.12133849 | X16: 0.028548587
A17: S07_KDM | B17: S02 | C17: SLOW | E17: 1 | F17: 346.189 | G17: 396.189 | H17: 50 | I17: 6.0213334 | J17: 12 | K17: 24 | L17: 0.80437058 | M17: 5.9200195 | N17: 5.8646906 | O17: 5.9200195 | P17: 0.15664281 | Q17: 0.10131389 | R17: 0.10131389 | S17: 4.7019022368096595 | T17: 0.009 | U17: 0.63016545 | V17: 0.13293545 | W17: 0.027744844 | X17: 0.031648521
A18: S07_KDM | B18: S02 | C18: SLOW | E18: 2 | F18: 346.189 | G18: 396.189 | H18: 50 | I18: 6.0213334 | J18: 20 | K18: 29 | L18: 0.77116332 | M18: 5.9314017 | N18: 5.8932067 | O18: 5.9314017 | P18: 0.12812673 | Q18: 0.0899317 | R18: 0.0899317 | S18: 3.711982828818849 | T18: 0.0025 | U18: 0.68940527 | V18: 0.13060799 | W18: 0.028220112 | X18: 0.029006981
A19: S07_KDM | B19: S02 | C19: SLOW | E19: 3 | F19: 346.189 | G19: 396.189 | H19: 50 | I19: 6.0213334 | J19: 14 | K19: 32 | L19: -0.81474304 | M19: 5.9797552 | N19: 5.9477077 | O19: 5.9797552 | P19: 0.073625761 | Q19: 0.041578192 | R19: 0.041578192 | S19: 5.035364202920661 | T19: 0.002 | U19: 0.64616305 | V19: 0.1405307 | W19: 0.029128461 | X19: 0.027789822
A20: S07_KDM | B20: S02 | C20: POST_HOLD | E20: 1 | F20: 436.189 | G20: 486.189 | H20: 50 | I20: 11.412533 | J20: 13 | K20: 71 | L20: -0.71993507 | M20: 11.500329 | N20: 11.313121 | O20: 11.500329 | P20: 0.099412724 | Q20: 0.087795606 | R20: 0.087795606 | S20: 3.849803704571583 | T20: 0.0005 | U20: 0.66405731 | V20: 0.11378183 | W20: 0.038552011 | X20: 0.029144228
A21: S07_KDM | B21: S02 | C21: POST_HOLD | E21: 2 | F21: 436.189 | G21: 486.189 | H21: 50 | I21: 11.412533 | J21: 21 | K21: 62 | L21: 0.69898026 | M21: 11.726805 | N21: 11.889989 | O21: 11.726805 | P21: 0.47745596 | Q21: 0.3142719 | R21: 0.3142719 | S21: 1.1527258955839887 | T21: 0.001 | U21: 0.81153944 | V21: 0.081724411 | W21: 0.04816649 | X21: 0.032211252
A22: S07_KDM | B22: S02 | C22: POST_HOLD | E22: 3 | F22: 436.189 | G22: 486.189 | H22: 50 | I22: 11.412533 | J22: 58 | K22: 16 | L22: 0.79421587 | M22: 11.282329 | N22: 11.277713 | O22: 11.282329 | P22: 0.13482088 | Q22: 0.13020482 | R22: 0.13020482 | S22: 4.0988262426443836 | T22: 0.0 | U22: 0.65606564 | V22: 0.12076416 | W22: 0.037961876 | X22: 0.030958891
A23: S07_KDM | B23: S02 | C23: SQUAT | E23: 1 | F23: 511.189 | G23: 561.189 | H23: 50 | I23: 22.079795 | J23: 81 | K23: 22 | L23: 0.43970185 | M23: 14.366648 | N23: 14.462492 | O23: 14.366648 | P23: 7.6173027 | Q23: 7.7131472 | R23: 7.7131472 | S23: 1.0626669878482184 | T23: 0.05 | U23: 0.84929145 | V23: 0.072033775 | W23: 0.091041536 | X23: 0.073346927
A24: S07_KDM | B24: S02 | C24: SQUAT | E24: 2 | F24: 511.189 | G24: 561.189 | H24: 50 | I24: 22.079795 | J24: 42 | K24: 18 | L24: -0.57614255 | M24: 10.976912 | N24: 10.954205 | O24: 10.976912 | P24: 11.125589 | Q24: 11.102883 | R24: 11.102883 | S24: 0.7741008246792034 | T24: 0.0125 | U24: 0.81700622 | V24: 0.062997859 | W24: 0.03257009 | X24: 0.079579759
A25: S07_KDM | B25: S02 | C25: SQUAT | E25: 3 | F25: 511.189 | G25: 561.189 | H25: 50 | I25: 22.079795 | J25: 31 | M25: 11.71282 | N25: 11.712256 | O25: 11.71282 | P25: 10.367539 | Q25: 10.366975 | R25: 10.366975 | S25: 0.7738469407261818 | T25: 0.026 | U25: 0.89228877 | V25: 0.047838399 | W25: 0.045204266 | X25: 0.15569546
A26: S07_KDM | B26: S02 | C26: POST_EXERCISE | E26: 1 | F26: 586.189 | G26: 636.189 | H26: 50 | I26: 21.914253 | J26: 57 | K26: 18 | L26: -0.70617529 | M26: 21.865989 | N26: 21.76117 | O26: 21.865989 | P26: 0.15308298 | Q26: 0.04826436 | R26: 0.04826436 | S26: 1.7931716852923865 | T26: 0.0 | U26: 0.74272116 | V26: 0.084527634 | W26: 0.21268617 | X26: 0.032234432
A27: S07_KDM | B27: S02 | C27: POST_EXERCISE | E27: 2 | F27: 586.189 | G27: 636.189 | H27: 50 | I27: 21.914253 | J27: 64 | K27: 30 | L27: -0.49273123 | M27: 21.816558 | N27: 21.821438 | O27: 21.816558 | P27: 0.092815676 | Q27: 0.09769558 | R27: 0.09769558 | S27: 2.386918116424145 | T27: 0.006 | U27: 0.73221422 | V27: 0.083630473 | W27: 0.21369063 | X27: 0.029476407
A28: S07_KDM | B28: S02 | C28: POST_EXERCISE | E28: 3 | F28: 586.189 | G28: 636.189 | H28: 50 | I28: 21.914253 | J28: 58 | K28: 25 | L28: 0.75999574 | M28: 21.824771 | N28: 21.843625 | O28: 21.824771 | P28: 0.070628329 | Q28: 0.089481875 | R28: 0.089481875 | S28: 2.397515776520744 | T28: 0.0 | U28: 0.72755642 | V28: 0.10429208 | W28: 0.21406041 | X28: 0.03125472
A29: S08_MDO | B29: S01 | C29: FACE_R1 | D29: 1 | E29: 1 | F29: 36.98 | G29: 85.1 | H29: 48.12 | I29: 10.290275 | J29: 14 | K29: 28 | L29: -0.86545399 | M29: 10.31621 | N29: 10.300655 | O29: 10.31621 | P29: 0.010379662 | Q29: 0.025934873 | R29: 0.025934873 | S29: 2.055364330274059 | T29: 0.0015592515592515593 | U29: 0.66973992 | V29: 0.12528862 | W29: 0.021677575 | X29: 0.025058695
A30: S08_MDO | B30: S01 | C30: FACE_R1 | D30: 1 | E30: 2 | F30: 36.98 | G30: 85.1 | H30: 48.12 | I30: 10.290275 | J30: 19 | K30: 68 | L30: -0.76856686 | M30: 10.460557 | N30: 10.540893 | O30: 10.460557 | P30: 0.25061789 | Q30: 0.1702821 | R30: 0.1702821 | S30: 1.0257568773283763 | T30: 0.0 | U30: 0.73555537 | V30: 0.10085235 | W30: 0.025681546 | X30: 0.028124239
A31: S08_MDO | B31: S01 | C31: FACE_R1 | D31: 1 | E31: 3 | F31: 36.98 | G31: 85.1 | H31: 48.12 | I31: 10.290275 | J31: 59 | K31: 68 | L31: 0.8274467 | M31: 11.033514 | N31: 11.128124 | O31: 11.033514 | P31: 0.83784924 | Q31: 0.74323886 | R31: 0.74323886 | S31: 0.7793156484050936 | T31: 0.0 | U31: 0.81313303 | V31: 0.07737125 | W31: 0.035468735 | X31: 0.019185552
A32: S08_MDO | B32: S01 | C32: FACE_R2 | D32: 2 | E32: 1 | F32: 95.1 | G32: 146.8 | H32: 51.7 | I32: 10.433251 | J32: 57 | K32: 78 | L32: -0.84727675 | M32: 10.482726 | N32: 10.61474 | O32: 10.482726 | P32: 0.18148925 | Q32: 0.049474957 | R32: 0.049474957 | S32: 1.2481445089428156 | T32: 0.0 | U32: 0.73605644 | V32: 0.10776111 | W32: 0.026912333 | X32: 0.027306642
A33: S08_MDO | B33: S01 | C33: FACE_R2 | D33: 2 | E33: 2 | F33: 95.1 | G33: 146.8 | H33: 51.7 | I33: 10.433251 | J33: 20 | K33: 30 | L33: -0.88820058 | M33: 10.381755 | N33: 10.38101 | O33: 10.381755 | P33: 0.052240563 | Q33: 0.051495646 | R33: 0.051495646 | S33: 1.9796188658651315 | T33: 0.0 | U33: 0.66227709 | V33: 0.1297417 | W33: 0.023016836 | X33: 0.035140237
A34: S08_MDO | B34: S01 | C34: FACE_R2 | D34: 2 | E34: 3 | F34: 95.1 | G34: 146.8 | H34: 51.7 | I34: 10.433251 | J34: 59 | K34: 22 | L34: 0.83736752 | M34: 10.251072 | N34: 10.243153 | O34: 10.251072 | P34: 0.19009763 | Q34: 0.18217843 | R34: 0.18217843 | S34: 1.8726191982985916 | T34: 0.0 | U34: 0.62039286 | V34: 0.140719 | W34: 0.020719218 | X34: 0.022442727
A35: S08_MDO | B35: S01 | C35: FACE_R3 | D35: 3 | E35: 1 | F35: 156.8 | G35: 215.164 | H35: 58.364 | I35: 10.780079 | J35: 62 | K35: 12 | L35: -0.76527274 | M35: 10.832059 | N35: 10.781902 | O35: 10.832059 | P35: 0.0018226241 | Q35: 0.051980254 | R35: 0.051980254 | S35: 1.8928539549703798 | T35: 0.005569837189374464 | U35: 0.66201031 | V35: 0.1842294 | W35: 0.029698363 | X35: 0.030115209
A36: S08_MDO | B36: S01 | C36: FACE_R3 | D36: 3 | E36: 2 | F36: 156.8 | G36: 215.164 | H36: 58.364 | I36: 10.780079 | J36: 21 | K36: 67 | L36: 0.76215974 | M36: 10.873485 | N36: 11.009801 | O36: 10.873485 | P36: 0.22972148 | Q36: 0.093405761 | R36: 0.093405761 | S36: 2.7815626930026696 | T36: 0.000856898029134533 | U36: 0.66837423 | V36: 0.15114047 | W36: 0.033496677 | X36: 0.02968026
A37: S08_MDO | B37: S01 | C37: FACE_R3 | D37: 3 | E37: 3 | F37: 156.8 | G37: 215.164 | H37: 58.364 | I37: 10.780079 | J37: 60 | K37: 72 | L37: 0.6175049 | M37: 10.687887 | N37: 10.639887 | O37: 10.687887 | P37: 0.14019227 | Q37: 0.09219186 | R37: 0.09219186 | S37: 2.1035140908760614 | T37: 0.0021422450728363325 | U37: 0.71179055 | V37: 0.11882406 | W37: 0.027331448 | X37: 0.025555555
A38: S08_MDO | B38: S02 | C38: NORMAL | E38: 1 | F38: 278.17 | G38: 328.17 | H38: 50 | I38: 18.438432 | J38: 21 | K38: 14 | L38: -0.77643784 | M38: 18.42081 | N38: 18.45335 | O38: 18.42081 | P38: 0.014917309 | Q38: 0.017622029 | R38: 0.017622029 | S38: 2.6846135445376107 | T38: 0.0005 | U38: 0.68562853 | V38: 0.12280543 | W38: 0.15755583 | X38: 0.031204142
A39: S08_MDO | B39: S02 | C39: NORMAL | E39: 2 | F39: 278.17 | G39: 328.17 | H39: 50 | I39: 18.438432 | J39: 65 | K39: 27 | L39: -0.68575288 | M39: 18.457638 | N39: 18.456983 | O39: 18.457638 | P39: 0.018550118 | Q39: 0.019205812 | R39: 0.019205812 | S39: 4.785483956035966 | T39: 0.0095 | U39: 0.62622254 | V39: 0.14154777 | W39: 0.15761638 | X39: 0.031353275
A40: S08_MDO | B40: S02 | C40: NORMAL | E40: 3 | F40: 278.17 | G40: 328.17 | H40: 50 | I40: 18.438432 | J40: 85 | K40: 74 | L40: 0.72628714 | M40: 18.599925 | N40: 18.692619 | O40: 18.599925 | P40: 0.25418605 | Q40: 0.16149224 | R40: 0.16149224 | S40: 1.032656550537584 | T40: 0.0 | U40: 0.69563376 | V40: 0.13546849 | W40: 0.16154364 | X40: 0.021178582
A41: S08_MDO | B41: S02 | C41: SLOW | E41: 1 | F41: 338.17 | G41: 388.17 | H41: 50 | I41: 5.9659786 | J41: 64 | K41: 60 | L41: 0.84956187 | M41: 5.9574 | N41: 5.9328798 | O41: 5.9574 | P41: 0.033098781 | Q41: 0.0085786275 | R41: 0.0085786275 | S41: 3.535171257255561 | T41: 0.0 | U41: 0.58305593 | V41: 0.14886229 | W41: 0.02888133 | X41: 0.027327519
...

Sheet 실패사례
A1: 개발군 실패 사례
A2: 오차가 큰 순서로 고정했습니다. 이 목록은 독립검증 전에 알고리즘 한계를 설명하기 위한 개발 기록입니다.
A4: subject | B4: experiment | C4: state | D4: nominal_facing_radar | E4: start_s | F4: end_s | G4: duration_s | H4: rsp_rr_bpm | I4: radar1_rr_bpm | J4: radar2_rr_bpm | K4: radar3_rr_bpm | L4: radar1_primary_rr_bpm | M4: radar2_primary_rr_bpm | N4: radar3_primary_rr_bpm | O4: quality_best_radar | P4: quality_best_rr_bpm | Q4: consensus_rr_bpm | R4: radar_rr_mad_bpm | S4: edge_quality | T4: motion_quality | U4: max_motion_index | V4: confidence | W4: reject | X4: rr_abs_error | Y4: oracle_abs_error | Z4: waveform_abs_corr | AA4: median_motion_index
A5: S26_LDW | B5: S01 | C5: FACE_R2 | D5: 2 | E5: 85.4 | F5: 136.3 | G5: 50.9 | H5: 21.752906 | I5: 21.605194 | J5: 9.0820312 | K5: 9.0820312 | L5: 21.467306 | M5: 9.0820312 | N5: 9.0820312 | O5: 2 | P5: 9.0820312 | Q5: 9.0820312 | R5: 0 | S5: 0.0390625 | T5: 1 | U5: 0.031167553 | V5: 0.6557570199618958 | W5: 1 | X5: 12.670875 | Y5: 0.14771223 | Z5: 0.33318579 | AA5: 0.028236732
A6: S23_KDM | B6: S02 | C6: POST_HOLD | E6: 391.608 | F6: 441.608 | G6: 50 | H6: 14.954701 | I6: 10.728545 | J6: 11.227226 | K6: 11.671301 | L6: 10.727307 | M6: 11.001105 | N6: 11.678136 | O6: 3 | P6: 11.671301 | Q6: 11.227226 | R6: 0.44407585 | S6: 0.95290692 | T6: 1 | U6: 0.028216892 | V6: 0.7761328421837292 | W6: 0 | X6: 3.7274755 | Y6: 3.2833996 | Z6: 0.38125301 | AA6: 0.026102771
A7: S17_RJS | B7: S02 | C7: POST_HOLD | E7: 393.25 | F7: 443.63 | G7: 50.38 | H7: 15.953072 | I7: 12.322079 | J7: 12.2716 | K7: 12.146666 | L7: 12.390901 | M7: 12.278132 | N7: 11.995747 | O7: 3 | P7: 12.146666 | Q7: 12.2716 | R7: 0.050479236 | S7: 1 | T7: 1 | U7: 0.02916279 | V7: 0.8606799817446732 | W7: 0 | X7: 3.681472 | Y7: 3.6309928 | Z7: 0.58739128 | AA7: 0.026706275
A8: S26_LDW | B8: S02 | C8: POST_HOLD | E8: 420.096 | F8: 470.096 | G8: 50 | H8: 18.600868 | I8: 22.457609 | J8: 21.506687 | K8: 21.884487 | L8: 22.409848 | M8: 21.505869 | N8: 21.810936 | O8: 3 | P8: 21.884487 | Q8: 21.884487 | R8: 0.37780004 | S8: 1 | T8: 1 | U8: 0.031941188 | V8: 0.8031687185572721 | W8: 0 | X8: 3.2836192 | Y8: 2.9058192 | Z8: 0.61270047 | AA8: 0.029614323
A9: S09_HDH | B9: S02 | C9: POST_EXERCISE | E9: 584.862 | F9: 634.862 | G9: 50 | H9: 13.804994 | I9: 15.999591 | J9: 11.483685 | K9: 10.717028 | L9: 16.000948 | M9: 11.598242 | N9: 10.502264 | O9: 2 | P9: 11.483685 | Q9: 11.483685 | R9: 0.766657 | S9: 1 | T9: 1 | U9: 0.034340076 | V9: 0.7365092092312489 | W9: 0 | X9: 2.3213089 | Y9: 2.1945969 | Z9: 0.22611498 | AA9: 0.032433696
A10: S26_LDW | B10: S01 | C10: FACE_R1 | D10: 1 | E10: 24.716 | F10: 75.4 | G10: 50.684 | H10: 25.774624 | I10: 24.062547 | J10: 26.624966 | K10: 11.159692 | L10: 24.059089 | M10: 26.573398 | N10: 11.660497 | O10: 1 | P10: 24.062547 | Q10: 24.062547 | R10: 2.5624188 | S10: 1 | T10: 1 | U10: 0.030048665 | V10: 0.6273739154457766 | W10: 0 | X10: 1.7120772 | Y10: 0.85034163 | Z10: 0.54577369 | AA10: 0.025856247
A11: S23_KDM | B11: S02 | C11: POST_EXERCISE | E11: 541.608 | F11: 591.608 | G11: 50 | H11: 38.452148 | I11: 37.412439 | J11: 37.129498 | K11: 10.840063 | L11: 37.458326 | M11: 37.213071 | N11: 10.838905 | O11: 2 | P11: 37.129498 | Q11: 37.129498 | R11: 0.28294086 | S11: 1 | T11: 1 | U11: 0.032253724 | V11: 0.8200233397538171 | W11: 0 | X11: 1.3226501 | Y11: 1.0397092 | Z11: 0.26040509 | AA11: 0.032156651
A12: S07_KDM | B12: S02 | C12: NORMAL | E12: 286.189 | F12: 336.189 | G12: 50 | H12: 15.587172 | I12: 16.201647 | J12: 14.08496 | K12: 16.272127 | L12: 16.272527 | M12: 14.146643 | N12: 16.280309 | O12: 3 | P12: 16.272127 | Q12: 16.201647 | R12: 0.070479517 | S12: 1 | T12: 1 | U12: 0.031215165 | V12: 0.8547197311618137 | W12: 0 | X12: 0.61447497 | Y12: 0.61447497 | Z12: 0.67641054 | AA12: 0.030431163
A13: S23_KDM | B13: S01 | C13: FACE_R2 | D13: 2 | E13: 82.5 | F13: 134.7 | G13: 52.2 | H13: 12.367004 | I13: 11.856508 | J13: 11.873551 | K13: 11.831707 | L13: 11.920245 | M13: 11.895547 | N13: 11.819985 | O13: 3 | P13: 11.831707 | Q13: 11.856508 | R13: 0.017043425 | S13: 1 | T13: 1 | U13: 0.028441038 | V13: 0.860650830913897 | W13: 0 | X13: 0.51049598 | Y13: 0.49345255 | Z13: 0.71873067 | AA13: 0.027401738
A14: S21_PSJ | B14: S01 | C14: FACE_R2 | D14: 2 | E14: 86.4 | F14: 138.4 | G14: 52 | H14: 11.079927 | I14: 11.486134 | J14: 11.47588 | K14: 10.977338 | L14: 11.300148 | M14: 11.335646 | N14: 11.043784 | O14: 2 | P14: 11.47588 | Q14: 11.47588 | R14: 0.010253846 | S14: 1 | T14: 1 | U14: 0.033169638 | V14: 0.8681669703629916 | W14: 0 | X14: 0.39595226 | Y14: 0.10258955 | Z14: 0.73323829 | AA14: 0.027601429
A15: S23_KDM | B15: S01 | C15: FACE_R3 | D15: 3 | E15: 144.7 | F15: 207.8 | G15: 63.1 | H15: 10.79734 | I15: 10.899356 | J15: 11.005979 | K15: 11.152718 | L15: 10.910502 | M15: 10.935519 | N15: 11.227134 | O15: 3 | P15: 11.152718 | Q15: 11.152718 | R15: 0.10662328 | S15: 0.9216755 | T15: 1 | U15: 0.033065804 | V15: 0.8579866493187642 | W15: 0 | X15: 0.35537807 | Y15: 0.10201582 | Z15: 0.52985321 | AA15: 0.029165901
A16: S21_PSJ | B16: S02 | C16: POST_EXERCISE | E16: 548.808 | F16: 598.808 | G16: 50 | H16: 27.32409 | I16: 27.75763 | J16: 27.515833 | K16: 27.671731 | L16: 27.722173 | M16: 27.556164 | N16: 27.683629 | O16: 3 | P16: 27.671731 | Q16: 27.671731 | R16: 0.085899169 | S16: 1 | T16: 1 | U16: 0.031971652 | V16: 0.8866767068315965 | W16: 0 | X16: 0.34764087 | Y16: 0.19174349 | Z16: 0.94392895 | AA16: 0.031876604
A17: S07_KDM | B17: S01 | C17: FACE_R2 | D17: 2 | E17: 89.4 | F17: 141.3 | G17: 51.9 | H17: 17.278966 | I17: 16.952714 | J17: 17.043484 | K17: 16.871437 | L17: 16.982492 | M17: 17.216889 | N17: 16.790587 | O17: 1 | P17: 16.952714 | Q17: 16.952714 | R17: 0.081276306 | S17: 1 | T17: 1 | U17: 0.029611614 | V17: 0.8486230480034661 | W17: 0 | X17: 0.32625217 | Y17: 0.23548219 | Z17: 0.85616043 | AA17: 0.028282656
A18: S26_LDW | B18: S01 | C18: FACE_R3 | D18: 3 | E18: 146.3 | F18: 201.844 | G18: 55.544 | H18: 23.739342 | I18: 23.822065 | J18: 23.996099 | K18: 23.92781 | L18: 23.896817 | M18: 23.991595 | N18: 24.015524 | O18: 2 | P18: 23.996099 | Q18: 23.996099 | R18: 0.06828953 | S18: 1 | T18: 1 | U18: 0.02858375 | V18: 0.8721101775812391 | W18: 0 | X18: 0.25675766 | Y18: 0.082723805 | Z18: 0.64788004 | AA18: 0.027421955
A19: S09_HDH | B19: S01 | C19: FACE_R2 | D19: 2 | E19: 90.9 | F19: 141.9 | G19: 51 | H19: 16.802957 | I19: 16.761512 | J19: 16.592185 | K19: 16.532136 | L19: 16.929712 | M19: 17.165256 | N19: 16.601414 | O19: 3 | P19: 16.532136 | Q19: 16.592185 | R19: 0.060049275 | S19: 1 | T19: 1 | U19: 0.028333324 | V19: 0.8699417531824182 | W19: 0 | X19: 0.21077178 | Y19: 0.04144528 | Z19: 0.74034318 | AA19: 0.027165917

Sheet 설정값
A1: 동결할 신호처리·거절 설정값
A2: 독립검증군을 실행하기 전에 아래 값을 변경하지 않는 것이 원칙입니다.
A4: group | B4: parameter | C4: value | D4: basis
A5: 신호 | B5: radar_fs_hz | C5: 40 | D5: 원시 레이더 설정
A6: 신호 | B6: range_bins | C6: 92 | D6: I/Q 184개=92쌍
A7: 호흡대역 | B7: S01/NORMAL low-high | C7: 0.15-0.45/0.50 Hz | D7: 정상 호흡 프로토콜 및 drift 억제
A8: 호흡대역 | B8: SLOW low-high | C8: 0.07-0.40 Hz | D8: 유도된 느린 호흡 허용
A9: 호흡대역 | B9: POST_HOLD | C9: 0.15-0.55 Hz | D9: 회복 호흡
A10: 호흡대역 | B10: POST_EXERCISE | C10: 0.15-0.65 Hz | D10: 운동 후 빠른 호흡
A11: 경로 | B11: 보조 후보 bin separation | C11: >=4 bins | D11: 인접 bin 중복 억제
A12: 경로 | B12: 보조 후보 RR difference | C12: <=0.03 Hz | D12: 동일 호흡원 후보
A13: 경로 | B13: 보조 후보 abs correlation | C13: >=0.35 | D13: 파형 유사성
A14: 레이더융합 | B14: outlier rejection | C14: median ±3 bpm | D14: 세 레이더 합의
A15: 거절 | B15: confidence | C15: <0.58 | D15: 개발군 고정
A16: 거절 | B16: radar RR MAD | C16: >4 bpm | D16: 레이더 불일치
A17: 거절 | B17: max motion index | C17: >0.055 | D17: 스쿼트 움직임 분리
A18: 거절 | B18: non-slow edge quality | C18: <0.25 | D18: 대역 하단 drift 피크 거절

Sheet 판단기록
A1: 판단 및 변경 이력
A2: 무엇을 바꿨고 왜 바꿨는지, 결과에 어떤 영향을 주는지 기록합니다.
A4: date | B4: decision | C4: basis | D4: impact
A5: 2026-09-01 | B5: 최종 목표 변경 | C5: 방향 분류를 최종 출력으로 두지 않고 방향 적응형 호흡수·파형·신뢰도 출력으로 전환 | D5: 기존 SNN은 파일럿으로 보관
A6: 2026-09-01 | B6: 10명 개발군 고정 | C6: 이미 결과를 본 참가자이므로 개발 전용 | D6: 나머지 17명은 규칙 동결 후 독립검증
A7: 2026-09-01 | B7: S12 M04=646.804 | C7: 기존 764.472는 S02 494초; 대체 원후보 사용 시 376.356초 | D7: S01·S02 공통 사용 가능
A8: 2026-09-01 | B8: S16 M04=654.944 | C8: 기존 759.140은 S02 477초; 대체 원후보 사용 시 372.932초 | D8: S01·S02 공통 사용 가능
A9: 2026-09-01 | B9: 비느린호흡 하한 0.15 Hz | C9: 0.08~0.12 Hz 잔여 drift가 여러 bin에서 동일 피크로 선택됨; 정상·회복·운동후 프로토콜 사전범위 적용 | D9: 개발군 전체 MAE 2.84→0.50회/분; 독립검증 전 고정
A10: 2026-09-01 | B10: 움직임 거절 임계값 max motion>0.055 | C10: 개발군 비스쿼트 최대 0.043, 스쿼트 9명 0.07 이상 | D10: 스쿼트 9/10 검출, 비스쿼트 오검출 0; S18 예정구간은 움직임 미관측
A11: 2026-09-01 | B11: 보조 경로 후보 용어 | C11: 빈 환경·실험실 기하 정보가 없어 물리 ghost 확정 불가 | D11: 보고서에서 ghost 단정 금지
A12: 2026-09-01 | B12: ANN/SNN 보류 | C12: 신뢰도가 포착하지 못하는 post-hold 실패가 남음 | D12: 기준선과 거절 규칙을 먼저 검증
